Workbook

Sheet COVER
A1: WATER SUPPLY PIPE SIZING TOOL
A2: Hazen-Williams · HDPE PE100 DIN 8074 (Gentex) · Uganda Water Supply Design Manual – 2nd Edition
A4: PROJECT INFORMATION
A5: Project Title
A6: Project Location
A7: Designed By
A8: Checked By
A9: Client / Owner
A10: Contract No.
A11: Date | B11: 02-May-2026
A12: Revision | B12: Rev 0
A14: DESIGN SUMMARY (auto-populated from calculation sheets)
A15: Description | B15: Value | C15: Unit | D15: Source Sheet
A16: Total Dynamic Head (TDH) | B16: =IFERROR(TDH_CALC!$E$43,"-") | C16: m | D16: TDH_CALC
A17: Design Flow Rate | B17: =IFERROR(TDH_CALC!$E$9,"-") | C17: L/s | D17: TDH_CALC
A18: Estimated Motor Power Required | B18: =IFERROR(TDH_CALC!$E$51,"-") | C18: kW | D18: TDH_CALC
A19: Transmission Main — Total Length | B19: =IFERROR(SUM(TRANSMISSION!$D$16:$D$30),"-") | C19: m | D19: TRANSMISSION
A20: Distribution Network — Total Length | B20: =IFERROR(SUM(DISTRIBUTION!$D$22:$D$41),"-") | C20: m | D20: DISTRIBUTION
A22: CELL COLOUR CODING
A23: Input Cell (yellow bg, dark-blue text) | B23: Enter data here
A24: Formula / Calculated (black text) | B24: Do not edit — auto-calculated
A25: Cross-sheet Link (green text) | B25: References another sheet
A26: ✓ OK — within design limits | B26: Velocity and pressure acceptable
A27: ⚠ Warning / Out of Range | B27: Action required — revise design
A29: WORKSHEET GUIDE
A30: Sheet | B30: Purpose | C30: Instructions
A31: PARAMETERS | B31: Design constants — H-W C, velocities, pressure ratings, demand factors | C31: Review and adjust defaults before running calculations
A32: PIPE_DB | B32: Full HDPE PE100 catalog (Gentex DIN 8074) — 74 entries OD 20–450 mm | C32: Do NOT modify — auto-referenced by all formulas
A33: TDH_CALC | B33: Total Dynamic Head: production well → storage reservoir; pump sizing | C33: Step 1 — enter well & reservoir survey data
A34: TRANSMISSION | B34: Transmission main — auto OD & PN selection, HGL profile, status checks | C34: Step 2 — enter segment lengths & elevations
A35: DISTRIBUTION | B35: Distribution network — demand calc, branch sizing, node pressure checks | C35: Step 3 — enter branch data; link HGL Start to junction nodes

Sheet PARAMETERS
A1: DESIGN PARAMETERS
A3: # | B3: Parameter | C3: Value | D3: Unit | E3: Reference / Notes
A4: HYDRAULIC PARAMETERS
A5: 1 | B5: Hazen-Williams Coefficient C (HDPE PE100) | C5: 150 | D5: - | E5: DIN 8074; Uganda WSS DM Sect 4.3
A6: 2 | B6: Min. Flow Velocity — Transmission Main | C6: 0.5 | D6: m/s | E6: Sedimentation prevention; Uganda WSS DM
A7: 3 | B7: Max. Flow Velocity — Transmission Main | C7: 2.5 | D7: m/s | E7: Erosion / surge limit for HDPE
A8: 4 | B8: Min. Flow Velocity — Distribution | C8: 0.3 | D8: m/s | E8: Sedimentation prevention; Uganda WSS DM
A9: 5 | B9: Max. Flow Velocity — Distribution | C9: 1.5 | D9: m/s | E9: Erosion limit; Uganda WSS DM
A10: 6 | B10: Minor Loss Factor k (fraction of friction loss) | C10: 0.05 | D10: - | E10: Typical for well-aligned mains; adjust per design
A12: PRESSURE RATINGS — HDPE PE100 DIN 8074 (PE100 compound)
A13: 7 | B13: PN-6 Max. Working Head | C13: 61.2 | D13: m | E13: 6 bar → 61.2 m H₂O (design limit = PN head ÷ SF)
A14: 8 | B14: PN-10 Max. Working Head | C14: 102 | D14: m | E14: 10 bar → 102.0 m H₂O
A15: 9 | B15: PN-16 Max. Working Head | C15: 163.2 | D15: m | E15: 16 bar → 163.2 m H₂O
A16: 10 | B16: PN-20 Max. Working Head | C16: 204 | D16: m | E16: 20 bar → 204.0 m H₂O
A17: 11 | B17: Pressure Safety Factor | C17: 1.25 | D17: - | E17: Design working head = PN head ÷ SF
A19: DESIGN STANDARDS — Uganda Water Supply Design Manual, 2nd Edition
A20: 12 | B20: Min. Residual Pressure — Distribution Consumer | C20: 7 | D20: m | E20: Rural WSS; Uganda WSS DM Sect 5
A21: 13 | B21: Min. Residual Pressure — Reservoir / Trans. End | C21: 2 | D21: m | E21: Above reservoir HWL at delivery point
A22: 14 | B22: Allowable Head Loss Gradient — Transmission | C22: 5 | D22: m/km | E22: Economic gradient; Uganda WSS DM
A23: 15 | B23: Allowable Head Loss Gradient — Distribution | C23: 8 | D23: m/km | E23: Economic gradient; Uganda WSS DM
A24: 16 | B24: Pump Design Operating Hours per Day | C24: 8 | D24: hr/day | E24: Uganda WSS DM rural standard
A26: DEMAND PARAMETERS
A27: 17 | B27: Per Capita Demand | C27: 20 | D27: L/cap/day | E27: Uganda rural WSS standard; adjust to local survey
A28: 18 | B28: Peak Hour Factor (PHF) | C28: 2 | D28: - | E28: Ratio of peak hour to average hourly demand
A29: 19 | B29: Peak Day Factor (PDF) | C29: 1.5 | D29: - | E29: Ratio of peak day to average daily demand
A30: 20 | B30: NRW / Loss Factor | C30: 1.2 | D30: - | E30: 20% non-revenue water allowance
A31: 21 | B31: Population Growth Rate | C31: 0.03 | D31: /yr | E31: 3% per year; verify against census data
A32: 22 | B32: Design Period | C32: 20 | D32: years | E32: Standard for Uganda rural water supply projects

Sheet PIPE_DB
A1: HDPE PE100 PIPE CATALOG — DIN 8074 | Gentex
A2: Source: Gentex HDPE Pipes – PE 100 – DIN 8074 Price List (effective July 6, 2018) | OD 20–90mm: 100m rolls | OD 110mm: 50m rolls | OD ≥125mm: 6m or 12m lengths
A3: Item Code | B3: OD (mm) | C3: PN Rating | D3: PN (Numeric) | E3: Internal Dia. ID (mm) | F3: Wall Thickness (mm) | G3: Weight (kg/m) | H3: Price (UGX/m) | I3: Supply Form
A4: 5001 | B4: 20 | C4: PN - 6 | D4: 6 | E4: 16.4 | F4: 1.8 | G4: 0.1 | H4: 1400 | I4: 100m roll
A5: 5002 | B5: 20 | C5: PN - 10 | D5: 10 | E5: 16.2 | F5: 1.9 | G5: 0.11 | H5: 1500 | I5: 100m roll
A6: 5003 | B6: 20 | C6: PN - 16 | D6: 16 | E6: 16.2 | F6: 1.9 | G6: 0.116 | H6: 1700 | I6: 100m roll
A7: 5011 | B7: 25 | C7: PN - 6 | D7: 6 | E7: 21.4 | F7: 1.8 | G7: 0.127 | H7: 1800 | I7: 100m roll
A8: 5012 | B8: 25 | C8: PN - 10 | D8: 10 | E8: 20.4 | F8: 2.3 | G8: 0.165 | H8: 2400 | I8: 100m roll
A9: 5013 | B9: 25 | C9: PN - 16 | D9: 16 | E9: 20.4 | F9: 2.3 | G9: 0.186 | H9: 2700 | I9: 100m roll
A10: 5022 | B10: 32 | C10: PN - 6 | D10: 6 | E10: 28.2 | F10: 1.9 | G10: 0.18 | H10: 2600 | I10: 100m roll
A11: 5023 | B11: 32 | C11: PN - 10 | D11: 10 | E11: 26.6 | F11: 2.7 | G11: 0.255 | H11: 3600 | I11: 100m roll
A12: 5024 | B12: 32 | C12: PN - 16 | D12: 16 | E12: 26.2 | F12: 2.9 | G12: 0.286 | H12: 4000 | I12: 100m roll
A13: 5032 | B13: 40 | C13: PN - 6 | D13: 6 | E13: 35.4 | F13: 2.3 | G13: 0.26 | H13: 3800 | I13: 100m roll
A14: 5033 | B14: 40 | C14: PN - 10 | D14: 10 | E14: 34.6 | F14: 2.7 | G14: 0.336 | H14: 4900 | I14: 100m roll
A15: 5034 | B15: 40 | C15: PN - 16 | D15: 16 | E15: 32.6 | F15: 3.7 | G15: 0.44 | H15: 6300 | I15: 100m roll
... A42: 5095 | B42: 160 | C42: PN - 20 | D42: 20 | E42: 124.2 | F42: 17.9 | G42: 8.39 | H42: 125900 | I42: 6m / 12m lengths
A43: 5220 | B43: 180 | C43: PN - 6 | D43: 6 | E43: 159.6 | F43: 10.2 | G43: 4 | I43: 6m / 12m lengths
A44: 5249 | B44: 180 | C44: PN - 10 | D44: 10 | E44: 158.6 | F44: 10.7 | G44: 6 | I44: 6m / 12m lengths
A45: 5250 | B45: 180 | C45: PN - 16 | D45: 16 | E45: 147.2 | F45: 16.4 | G45: 8.83 | I45: 6m / 12m lengths
A46: 5251 | B46: 180 | C46: PN - 20 | D46: 20 | E46: 139.8 | F46: 20.1 | G46: 10.6 | I46: 6m / 12m lengths
A47: 5230 | B47: 200 | C47: PN - 06 | D47: 6 | E47: 185.6 | F47: 7.2 | G47: 4.6 | I47: 6m / 12m lengths
A48: 5253 | B48: 200 | C48: PN - 10 | D48: 10 | E48: 176.2 | F48: 11.9 | G48: 7.39 | I48: 6m / 12m lengths
A49: 5254 | B49: 200 | C49: PN - 16 | D49: 16 | E49: 163.6 | F49: 18.2 | G49: 10.9 | I49: 6m / 12m lengths
A50: 5255 | B50: 200 | C50: PN - 20 | D50: 20 | E50: 155.2 | F50: 22.4 | G50: 13.12 | I50: 6m / 12m lengths
A51: 5240 | B51: 225 | C51: PN - 06 | D51: 6 | E51: 208.6 | F51: 8.2 | G51: 5.83 | I51: 6m / 12m lengths
A52: 5257 | B52: 225 | C52: PN - 10 | D52: 10 | E52: 198.2 | F52: 13.4 | G52: 9.38 | I52: 6m / 12m lengths
A53: 5258 | B53: 225 | C53: PN - 16 | D53: 16 | E53: 184 | F53: 20.5 | G53: 13.79 | I53: 6m / 12m lengths
A54: 5259 | B54: 225 | C54: PN - 20 | D54: 20 | E54: 174.6 | F54: 25.2 | G54: 16.6 | I54: 6m / 12m lengths
... A77: 5282 | B77: 450 | C77: PN - 16 | D77: 16 | E77: 368.2 | F77: 40.9 | G77: 55.17 | I77: 6m / 12m lengths

Sheet TDH_CALC
A1: TOTAL DYNAMIC HEAD (TDH) CALCULATION
A2: Production Well → Storage Reservoir | Hazen-Williams | HDPE PE100 | Uganda WSS DM 2nd Ed.
A4: SECTION 1 — SITE & WELL DATA (enter survey / pump test data)
A5: Ground Elevation at Wellhead | F5: m ASL | G5: From topographic survey
A6: Static Water Level (SWL) | F6: m bgl | G6: Measured with pump off
A7: Pumping / Dynamic Water Level (PWL) | F7: m bgl | G7: From pump test at design flow
A8: Pump Setting Depth | F8: m bgl | G8: Depth of pump intake below ground surface
A9: Design Flow Rate Q | F9: L/s | G9: Pump design capacity
A10: Pump Operating Hours per Day | E10: =PARAMETERS!$C$24 | F10: hr/day | G10: From PARAMETERS — adjust if needed
A11: Reservoir Floor Elevation | F11: m ASL | G11: From topographic survey
A12: Reservoir High Water Level (HWL) | F12: m ASL | G12: Full storage level
A13: Required Minimum Water Level in Reservoir | F13: m ASL | G13: Floor elevation + minimum operational storage depth
A15: SECTION 2 — DERIVED ELEVATIONS
A16: Elevation of Pumping Water Level | E16: =IFERROR(E5-E7,"") | F16: m ASL
A17: Elevation of Static Water Level | E17: =IFERROR(E5-E6,"") | F17: m ASL
A18: Minimum Static Head Required (HWL – Pumping WL Elevation) | E18: =IFERROR(E12-(E5-E7),"") | F18: m
A20: SECTION 3 — RISING MAIN / DISCHARGE PIPELINE SEGMENTS
A21: Enter each segment from pump level to reservoir. Segment 1 = pump column (From Elev = Ground Elev – Pump Setting Depth; To Elev = Ground Elev at wellhead). Subsequent segments = surface pipeline to reservoir. Allow. S (col H) defaults to transmission standard — override per segment if needed. OD, PN Rating, and ID are auto-selected from PIPE_DB. Rows with Length = 0 are skipped.
A22: # | B22: Segment Description | C22: Length (m) | D22: From Elev (m ASL) | E22: To Elev (m ASL) | F22: ΔElev (m) | G22: Q (L/s) | H22: Allow. S (m/km) | I22: Min D_req (mm) | J22: Auto OD (mm) | K22: Auto PN Num | L22: Auto PN Rating | M22: Actual ID (mm) | N22: Velocity (m/s) | O22: Friction hf (m) | P22: Minor Loss (m) | Q22: Total Loss (m) | R22: Max Press. In Seg (m) | S22: Status
A23: 1 | B23: Pump Column (inside well casing) | F23: =IF(OR(D23="",E23=""),"",E23-D23) | G23: $E$9 | H23: =PARAMETERS!$C$22 | I23: =IF(G23<=0,"""",IFERROR(MAX(1000*((10.67*(G23/1000)^1.852)/(PARAMETERS!$C$5^1.852*(H23/1000)))^(1/4.87),1000*SQRT(4*(G23/1000)/(PI()*PARAMETERS!$C$7))),0)) | J23: =IF(OR(G23<=0,I23=""""),"""",IFERROR(AGGREGATE(15,6,PIPE_DB!$B$4:$B$77/((PIPE_DB!$E$4:$E$77>=I23)*(PIPE_DB!$D$4:$D$77=K23)),1),"SIZE N/A")) | K23: =IF(R23="""","""",IF(R23<=PARAMETERS!$C$13/PARAMETERS!$C$17,6,IF(R23<=PARAMETERS!$C$14/PARAMETERS!$C$17,10,IF(R23<=PARAMETERS!$C$15/PARAMETERS!$C$17,16,20)))) | L23: =IF(K23="""","""",IF(K23=6,"PN - 6",IF(K23=10,"PN - 10",IF(K23=16,"PN - 16","PN - 20")))) | M23: =IF(OR(J23="""",J23="SIZE N/A",NOT(ISNUMBER(J23))),"""",IFERROR(SUMPRODUCT((PIPE_DB!$B$4:$B$77=J23)*(PIPE_DB!$D$4:$D$77=K23)*PIPE_DB!$E$4:$E$77),0)) | N23: =IF(OR(G23<=0,M23="""",NOT(ISNUMBER(M23))),"""",IFERROR(4*(G23/1000)/(PI()*(M23/1000)^2),0)) | O23: =IF(OR(G23<=0,M23="""",NOT(ISNUMBER(M23))),"""",IFERROR(10.67*C23*(G23/1000)^1.852/(PARAMETERS!$C$5^1.852*(M23/1000)^4.87),0)) | P23: =IF(O23="""","""",IFERROR(PARAMETERS!$C$10*O23,0)) | Q23: =IF(O23="""","""",IFERROR(O23+P23,0)) | R23: =IF(OR(D23="",E23=""),"",IFERROR($E$12-MIN(D23,E23),0)) | S23: =IF(J23="""","""",IF(J23="SIZE N/A","⚠ SIZE N/A",IF(N23="""","""",IF(AND(N23>=PARAMETERS!$C$6,N23<=PARAMETERS!$C$7,IFERROR($E$12-E23,0)>=PARAMETERS!$C$21),"✓ OK",IF(N23<PARAMETERS!$C$6,"⚠ LOW VELOCITY",IF(N23>PARAMETERS!$C$7,"⚠ HIGH VELOCITY","⚠ LOW PRESSURE"))))))
A24: 2 | B24: Surface Rising Main — Segment 1 | F24: =IF(OR(D24="",E24=""),"",E24-D24) | G24: $E$9 | H24: =PARAMETERS!$C$22 | I24: =IF(G24<=0,"""",IFERROR(MAX(1000*((10.67*(G24/1000)^1.852)/(PARAMETERS!$C$5^1.852*(H24/1000)))^(1/4.87),1000*SQRT(4*(G24/1000)/(PI()*PARAMETERS!$C$7))),0)) | J24: =IF(OR(G24<=0,I24=""""),"""",IFERROR(AGGREGATE(15,6,PIPE_DB!$B$4:$B$77/((PIPE_DB!$E$4:$E$77>=I24)*(PIPE_DB!$D$4:$D$77=K24)),1),"SIZE N/A")) | K24: =IF(R24="""","""",IF(R24<=PARAMETERS!$C$13/PARAMETERS!$C$17,6,IF(R24<=PARAMETERS!$C$14/PARAMETERS!$C$17,10,IF(R24<=PARAMETERS!$C$15/PARAMETERS!$C$17,16,20)))) | L24: =IF(K24="""","""",IF(K24=6,"PN - 6",IF(K24=10,"PN - 10",IF(K24=16,"PN - 16","PN - 20")))) | M24: =IF(OR(J24="""",J24="SIZE N/A",NOT(ISNUMBER(J24))),"""",IFERROR(SUMPRODUCT((PIPE_DB!$B$4:$B$77=J24)*(PIPE_DB!$D$4:$D$77=K24)*PIPE_DB!$E$4:$E$77),0)) | N24: =IF(OR(G24<=0,M24="""",NOT(ISNUMBER(M24))),"""",IFERROR(4*(G24/1000)/(PI()*(M24/1000)^2),0)) | O24: =IF(OR(G24<=0,M24="""",NOT(ISNUMBER(M24))),"""",IFERROR(10.67*C24*(G24/1000)^1.852/(PARAMETERS!$C$5^1.852*(M24/1000)^4.87),0)) | P24: =IF(O24="""","""",IFERROR(PARAMETERS!$C$10*O24,0)) | Q24: =IF(O24="""","""",IFERROR(O24+P24,0)) | R24: =IF(OR(D24="",E24=""),"",IFERROR($E$12-MIN(D24,E24),0)) | S24: =IF(J24="""","""",IF(J24="SIZE N/A","⚠ SIZE N/A",IF(N24="""","""",IF(AND(N24>=PARAMETERS!$C$6,N24<=PARAMETERS!$C$7,IFERROR($E$12-E24,0)>=PARAMETERS!$C$21),"✓ OK",IF(N24<PARAMETERS!$C$6,"⚠ LOW VELOCITY",IF(N24>PARAMETERS!$C$7,"⚠ HIGH VELOCITY","⚠ LOW PRESSURE"))))))
A25: 3 | B25: Surface Rising Main — Segment 2 | F25: =IF(OR(D25="",E25=""),"",E25-D25) | G25: $E$9 | H25: =PARAMETERS!$C$22 | I25: =IF(G25<=0,"""",IFERROR(MAX(1000*((10.67*(G25/1000)^1.852)/(PARAMETERS!$C$5^1.852*(H25/1000)))^(1/4.87),1000*SQRT(4*(G25/1000)/(PI()*PARAMETERS!$C$7))),0)) | J25: =IF(OR(G25<=0,I25=""""),"""",IFERROR(AGGREGATE(15,6,PIPE_DB!$B$4:$B$77/((PIPE_DB!$E$4:$E$77>=I25)*(PIPE_DB!$D$4:$D$77=K25)),1),"SIZE N/A")) | K25: =IF(R25="""","""",IF(R25<=PARAMETERS!$C$13/PARAMETERS!$C$17,6,IF(R25<=PARAMETERS!$C$14/PARAMETERS!$C$17,10,IF(R25<=PARAMETERS!$C$15/PARAMETERS!$C$17,16,20)))) | L25: =IF(K25="""","""",IF(K25=6,"PN - 6",IF(K25=10,"PN - 10",IF(K25=16,"PN - 16","PN - 20")))) | M25: =IF(OR(J25="""",J25="SIZE N/A",NOT(ISNUMBER(J25))),"""",IFERROR(SUMPRODUCT((PIPE_DB!$B$4:$B$77=J25)*(PIPE_DB!$D$4:$D$77=K25)*PIPE_DB!$E$4:$E$77),0)) | N25: =IF(OR(G25<=0,M25="""",NOT(ISNUMBER(M25))),"""",IFERROR(4*(G25/1000)/(PI()*(M25/1000)^2),0)) | O25: =IF(OR(G25<=0,M25="""",NOT(ISNUMBER(M25))),"""",IFERROR(10.67*C25*(G25/1000)^1.852/(PARAMETERS!$C$5^1.852*(M25/1000)^4.87),0)) | P25: =IF(O25="""","""",IFERROR(PARAMETERS!$C$10*O25,0)) | Q25: =IF(O25="""","""",IFERROR(O25+P25,0)) | R25: =IF(OR(D25="",E25=""),"",IFERROR($E$12-MIN(D25,E25),0)) | S25: =IF(J25="""","""",IF(J25="SIZE N/A","⚠ SIZE N/A",IF(N25="""","""",IF(AND(N25>=PARAMETERS!$C$6,N25<=PARAMETERS!$C$7,IFERROR($E$12-E25,0)>=PARAMETERS!$C$21),"✓ OK",IF(N25<PARAMETERS!$C$6,"⚠ LOW VELOCITY",IF(N25>PARAMETERS!$C$7,"⚠ HIGH VELOCITY","⚠ LOW PRESSURE"))))))
A26: 4 | B26: Surface Rising Main — Segment 3 | F26: =IF(OR(D26="",E26=""),"",E26-D26) | G26: $E$9 | H26: =PARAMETERS!$C$22 | I26: =IF(G26<=0,"""",IFERROR(MAX(1000*((10.67*(G26/1000)^1.852)/(PARAMETERS!$C$5^1.852*(H26/1000)))^(1/4.87),1000*SQRT(4*(G26/1000)/(PI()*PARAMETERS!$C$7))),0)) | J26: =IF(OR(G26<=0,I26=""""),"""",IFERROR(AGGREGATE(15,6,PIPE_DB!$B$4:$B$77/((PIPE_DB!$E$4:$E$77>=I26)*(PIPE_DB!$D$4:$D$77=K26)),1),"SIZE N/A")) | K26: =IF(R26="""","""",IF(R26<=PARAMETERS!$C$13/PARAMETERS!$C$17,6,IF(R26<=PARAMETERS!$C$14/PARAMETERS!$C$17,10,IF(R26<=PARAMETERS!$C$15/PARAMETERS!$C$17,16,20)))) | L26: =IF(K26="""","""",IF(K26=6,"PN - 6",IF(K26=10,"PN - 10",IF(K26=16,"PN - 16","PN - 20")))) | M26: =IF(OR(J26="""",J26="SIZE N/A",NOT(ISNUMBER(J26))),"""",IFERROR(SUMPRODUCT((PIPE_DB!$B$4:$B$77=J26)*(PIPE_DB!$D$4:$D$77=K26)*PIPE_DB!$E$4:$E$77),0)) | N26: =IF(OR(G26<=0,M26="""",NOT(ISNUMBER(M26))),"""",IFERROR(4*(G26/1000)/(PI()*(M26/1000)^2),0)) | O26: =IF(OR(G26<=0,M26="""",NOT(ISNUMBER(M26))),"""",IFERROR(10.67*C26*(G26/1000)^1.852/(PARAMETERS!$C$5^1.852*(M26/1000)^4.87),0)) | P26: =IF(O26="""","""",IFERROR(PARAMETERS!$C$10*O26,0)) | Q26: =IF(O26="""","""",IFERROR(O26+P26,0)) | R26: =IF(OR(D26="",E26=""),"",IFERROR($E$12-MIN(D26,E26),0)) | S26: =IF(J26="""","""",IF(J26="SIZE N/A","⚠ SIZE N/A",IF(N26="""","""",IF(AND(N26>=PARAMETERS!$C$6,N26<=PARAMETERS!$C$7,IFERROR($E$12-E26,0)>=PARAMETERS!$C$21),"✓ OK",IF(N26<PARAMETERS!$C$6,"⚠ LOW VELOCITY",IF(N26>PARAMETERS!$C$7,"⚠ HIGH VELOCITY","⚠ LOW PRESSURE"))))))
A27: 5 | F27: =IF(OR(D27="",E27=""),"",E27-D27) | G27: $E$9 | H27: =PARAMETERS!$C$22 | I27: =IF(G27<=0,"""",IFERROR(MAX(1000*((10.67*(G27/1000)^1.852)/(PARAMETERS!$C$5^1.852*(H27/1000)))^(1/4.87),1000*SQRT(4*(G27/1000)/(PI()*PARAMETERS!$C$7))),0)) | J27: =IF(OR(G27<=0,I27=""""),"""",IFERROR(AGGREGATE(15,6,PIPE_DB!$B$4:$B$77/((PIPE_DB!$E$4:$E$77>=I27)*(PIPE_DB!$D$4:$D$77=K27)),1),"SIZE N/A")) | K27: =IF(R27="""","""",IF(R27<=PARAMETERS!$C$13/PARAMETERS!$C$17,6,IF(R27<=PARAMETERS!$C$14/PARAMETERS!$C$17,10,IF(R27<=PARAMETERS!$C$15/PARAMETERS!$C$17,16,20)))) | L27: =IF(K27="""","""",IF(K27=6,"PN - 6",IF(K27=10,"PN - 10",IF(K27=16,"PN - 16","PN - 20")))) | M27: =IF(OR(J27="""",J27="SIZE N/A",NOT(ISNUMBER(J27))),"""",IFERROR(SUMPRODUCT((PIPE_DB!$B$4:$B$77=J27)*(PIPE_DB!$D$4:$D$77=K27)*PIPE_DB!$E$4:$E$77),0)) | N27: =IF(OR(G27<=0,M27="""",NOT(ISNUMBER(M27))),"""",IFERROR(4*(G27/1000)/(PI()*(M27/1000)^2),0)) | O27: =IF(OR(G27<=0,M27="""",NOT(ISNUMBER(M27))),"""",IFERROR(10.67*C27*(G27/1000)^1.852/(PARAMETERS!$C$5^1.852*(M27/1000)^4.87),0)) | P27: =IF(O27="""","""",IFERROR(PARAMETERS!$C$10*O27,0)) | Q27: =IF(O27="""","""",IFERROR(O27+P27,0)) | R27: =IF(OR(D27="",E27=""),"",IFERROR($E$12-MIN(D27,E27),0)) | S27: =IF(J27="""","""",IF(J27="SIZE N/A","⚠ SIZE N/A",IF(N27="""","""",IF(AND(N27>=PARAMETERS!$C$6,N27<=PARAMETERS!$C$7,IFERROR($E$12-E27,0)>=PARAMETERS!$C$21),"✓ OK",IF(N27<PARAMETERS!$C$6,"⚠ LOW VELOCITY",IF(N27>PARAMETERS!$C$7,"⚠ HIGH VELOCITY","⚠ LOW PRESSURE"))))))
A28: 6 | F28: =IF(OR(D28="",E28=""),"",E28-D28) | G28: $E$9 | H28: =PARAMETERS!$C$22 | I28: =IF(G28<=0,"""",IFERROR(MAX(1000*((10.67*(G28/1000)^1.852)/(PARAMETERS!$C$5^1.852*(H28/1000)))^(1/4.87),1000*SQRT(4*(G28/1000)/(PI()*PARAMETERS!$C$7))),0)) | J28: =IF(OR(G28<=0,I28=""""),"""",IFERROR(AGGREGATE(15,6,PIPE_DB!$B$4:$B$77/((PIPE_DB!$E$4:$E$77>=I28)*(PIPE_DB!$D$4:$D$77=K28)),1),"SIZE N/A")) | K28: =IF(R28="""","""",IF(R28<=PARAMETERS!$C$13/PARAMETERS!$C$17,6,IF(R28<=PARAMETERS!$C$14/PARAMETERS!$C$17,10,IF(R28<=PARAMETERS!$C$15/PARAMETERS!$C$17,16,20)))) | L28: =IF(K28="""","""",IF(K28=6,"PN - 6",IF(K28=10,"PN - 10",IF(K28=16,"PN - 16","PN - 20")))) | M28: =IF(OR(J28="""",J28="SIZE N/A",NOT(ISNUMBER(J28))),"""",IFERROR(SUMPRODUCT((PIPE_DB!$B$4:$B$77=J28)*(PIPE_DB!$D$4:$D$77=K28)*PIPE_DB!$E$4:$E$77),0)) | N28: =IF(OR(G28<=0,M28="""",NOT(ISNUMBER(M28))),"""",IFERROR(4*(G28/1000)/(PI()*(M28/1000)^2),0)) | O28: =IF(OR(G28<=0,M28="""",NOT(ISNUMBER(M28))),"""",IFERROR(10.67*C28*(G28/1000)^1.852/(PARAMETERS!$C$5^1.852*(M28/1000)^4.87),0)) | P28: =IF(O28="""","""",IFERROR(PARAMETERS!$C$10*O28,0)) | Q28: =IF(O28="""","""",IFERROR(O28+P28,0)) | R28: =IF(OR(D28="",E28=""),"",IFERROR($E$12-MIN(D28,E28),0)) | S28: =IF(J28="""","""",IF(J28="SIZE N/A","⚠ SIZE N/A",IF(N28="""","""",IF(AND(N28>=PARAMETERS!$C$6,N28<=PARAMETERS!$C$7,IFERROR($E$12-E28,0)>=PARAMETERS!$C$21),"✓ OK",IF(N28<PARAMETERS!$C$6,"⚠ LOW VELOCITY",IF(N28>PARAMETERS!$C$7,"⚠ HIGH VELOCITY","⚠ LOW PRESSURE"))))))
A29: 7 | F29: =IF(OR(D29="",E29=""),"",E29-D29) | G29: $E$9 | H29: =PARAMETERS!$C$22 | I29: =IF(G29<=0,"""",IFERROR(MAX(1000*((10.67*(G29/1000)^1.852)/(PARAMETERS!$C$5^1.852*(H29/1000)))^(1/4.87),1000*SQRT(4*(G29/1000)/(PI()*PARAMETERS!$C$7))),0)) | J29: =IF(OR(G29<=0,I29=""""),"""",IFERROR(AGGREGATE(15,6,PIPE_DB!$B$4:$B$77/((PIPE_DB!$E$4:$E$77>=I29)*(PIPE_DB!$D$4:$D$77=K29)),1),"SIZE N/A")) | K29: =IF(R29="""","""",IF(R29<=PARAMETERS!$C$13/PARAMETERS!$C$17,6,IF(R29<=PARAMETERS!$C$14/PARAMETERS!$C$17,10,IF(R29<=PARAMETERS!$C$15/PARAMETERS!$C$17,16,20)))) | L29: =IF(K29="""","""",IF(K29=6,"PN - 6",IF(K29=10,"PN - 10",IF(K29=16,"PN - 16","PN - 20")))) | M29: =IF(OR(J29="""",J29="SIZE N/A",NOT(ISNUMBER(J29))),"""",IFERROR(SUMPRODUCT((PIPE_DB!$B$4:$B$77=J29)*(PIPE_DB!$D$4:$D$77=K29)*PIPE_DB!$E$4:$E$77),0)) | N29: =IF(OR(G29<=0,M29="""",NOT(ISNUMBER(M29))),"""",IFERROR(4*(G29/1000)/(PI()*(M29/1000)^2),0)) | O29: =IF(OR(G29<=0,M29="""",NOT(ISNUMBER(M29))),"""",IFERROR(10.67*C29*(G29/1000)^1.852/(PARAMETERS!$C$5^1.852*(M29/1000)^4.87),0)) | P29: =IF(O29="""","""",IFERROR(PARAMETERS!$C$10*O29,0)) | Q29: =IF(O29="""","""",IFERROR(O29+P29,0)) | R29: =IF(OR(D29="",E29=""),"",IFERROR($E$12-MIN(D29,E29),0)) | S29: =IF(J29="""","""",IF(J29="SIZE N/A","⚠ SIZE N/A",IF(N29="""","""",IF(AND(N29>=PARAMETERS!$C$6,N29<=PARAMETERS!$C$7,IFERROR($E$12-E29,0)>=PARAMETERS!$C$21),"✓ OK",IF(N29<PARAMETERS!$C$6,"⚠ LOW VELOCITY",IF(N29>PARAMETERS!$C$7,"⚠ HIGH VELOCITY","⚠ LOW PRESSURE"))))))
A30: 8 | F30: =IF(OR(D30="",E30=""),"",E30-D30) | G30: $E$9 | H30: =PARAMETERS!$C$22 | I30: =IF(G30<=0,"""",IFERROR(MAX(1000*((10.67*(G30/1000)^1.852)/(PARAMETERS!$C$5^1.852*(H30/1000)))^(1/4.87),1000*SQRT(4*(G30/1000)/(PI()*PARAMETERS!$C$7))),0)) | J30: =IF(OR(G30<=0,I30=""""),"""",IFERROR(AGGREGATE(15,6,PIPE_DB!$B$4:$B$77/((PIPE_DB!$E$4:$E$77>=I30)*(PIPE_DB!$D$4:$D$77=K30)),1),"SIZE N/A")) | K30: =IF(R30="""","""",IF(R30<=PARAMETERS!$C$13/PARAMETERS!$C$17,6,IF(R30<=PARAMETERS!$C$14/PARAMETERS!$C$17,10,IF(R30<=PARAMETERS!$C$15/PARAMETERS!$C$17,16,20)))) | L30: =IF(K30="""","""",IF(K30=6,"PN - 6",IF(K30=10,"PN - 10",IF(K30=16,"PN - 16","PN - 20")))) | M30: =IF(OR(J30="""",J30="SIZE N/A",NOT(ISNUMBER(J30))),"""",IFERROR(SUMPRODUCT((PIPE_DB!$B$4:$B$77=J30)*(PIPE_DB!$D$4:$D$77=K30)*PIPE_DB!$E$4:$E$77),0)) | N30: =IF(OR(G30<=0,M30="""",NOT(ISNUMBER(M30))),"""",IFERROR(4*(G30/1000)/(PI()*(M30/1000)^2),0)) | O30: =IF(OR(G30<=0,M30="""",NOT(ISNUMBER(M30))),"""",IFERROR(10.67*C30*(G30/1000)^1.852/(PARAMETERS!$C$5^1.852*(M30/1000)^4.87),0)) | P30: =IF(O30="""","""",IFERROR(PARAMETERS!$C$10*O30,0)) | Q30: =IF(O30="""","""",IFERROR(O30+P30,0)) | R30: =IF(OR(D30="",E30=""),"",IFERROR($E$12-MIN(D30,E30),0)) | S30: =IF(J30="""","""",IF(J30="SIZE N/A","⚠ SIZE N/A",IF(N30="""","""",IF(AND(N30>=PARAMETERS!$C$6,N30<=PARAMETERS!$C$7,IFERROR($E$12-E30,0)>=PARAMETERS!$C$21),"✓ OK",IF(N30<PARAMETERS!$C$6,"⚠ LOW VELOCITY",IF(N30>PARAMETERS!$C$7,"⚠ HIGH VELOCITY","⚠ LOW PRESSURE"))))))
A31: 9 | F31: =IF(OR(D31="",E31=""),"",E31-D31) | G31: $E$9 | H31: =PARAMETERS!$C$22 | I31: =IF(G31<=0,"""",IFERROR(MAX(1000*((10.67*(G31/1000)^1.852)/(PARAMETERS!$C$5^1.852*(H31/1000)))^(1/4.87),1000*SQRT(4*(G31/1000)/(PI()*PARAMETERS!$C$7))),0)) | J31: =IF(OR(G31<=0,I31=""""),"""",IFERROR(AGGREGATE(15,6,PIPE_DB!$B$4:$B$77/((PIPE_DB!$E$4:$E$77>=I31)*(PIPE_DB!$D$4:$D$77=K31)),1),"SIZE N/A")) | K31: =IF(R31="""","""",IF(R31<=PARAMETERS!$C$13/PARAMETERS!$C$17,6,IF(R31<=PARAMETERS!$C$14/PARAMETERS!$C$17,10,IF(R31<=PARAMETERS!$C$15/PARAMETERS!$C$17,16,20)))) | L31: =IF(K31="""","""",IF(K31=6,"PN - 6",IF(K31=10,"PN - 10",IF(K31=16,"PN - 16","PN - 20")))) | M31: =IF(OR(J31="""",J31="SIZE N/A",NOT(ISNUMBER(J31))),"""",IFERROR(SUMPRODUCT((PIPE_DB!$B$4:$B$77=J31)*(PIPE_DB!$D$4:$D$77=K31)*PIPE_DB!$E$4:$E$77),0)) | N31: =IF(OR(G31<=0,M31="""",NOT(ISNUMBER(M31))),"""",IFERROR(4*(G31/1000)/(PI()*(M31/1000)^2),0)) | O31: =IF(OR(G31<=0,M31="""",NOT(ISNUMBER(M31))),"""",IFERROR(10.67*C31*(G31/1000)^1.852/(PARAMETERS!$C$5^1.852*(M31/1000)^4.87),0)) | P31: =IF(O31="""","""",IFERROR(PARAMETERS!$C$10*O31,0)) | Q31: =IF(O31="""","""",IFERROR(O31+P31,0)) | R31: =IF(OR(D31="",E31=""),"",IFERROR($E$12-MIN(D31,E31),0)) | S31: =IF(J31="""","""",IF(J31="SIZE N/A","⚠ SIZE N/A",IF(N31="""","""",IF(AND(N31>=PARAMETERS!$C$6,N31<=PARAMETERS!$C$7,IFERROR($E$12-E31,0)>=PARAMETERS!$C$21),"✓ OK",IF(N31<PARAMETERS!$C$6,"⚠ LOW VELOCITY",IF(N31>PARAMETERS!$C$7,"⚠ HIGH VELOCITY","⚠ LOW PRESSURE"))))))
A32: 10 | F32: =IF(OR(D32="",E32=""),"",E32-D32) | G32: $E$9 | H32: =PARAMETERS!$C$22 | I32: =IF(G32<=0,"""",IFERROR(MAX(1000*((10.67*(G32/1000)^1.852)/(PARAMETERS!$C$5^1.852*(H32/1000)))^(1/4.87),1000*SQRT(4*(G32/1000)/(PI()*PARAMETERS!$C$7))),0)) | J32: =IF(OR(G32<=0,I32=""""),"""",IFERROR(AGGREGATE(15,6,PIPE_DB!$B$4:$B$77/((PIPE_DB!$E$4:$E$77>=I32)*(PIPE_DB!$D$4:$D$77=K32)),1),"SIZE N/A")) | K32: =IF(R32="""","""",IF(R32<=PARAMETERS!$C$13/PARAMETERS!$C$17,6,IF(R32<=PARAMETERS!$C$14/PARAMETERS!$C$17,10,IF(R32<=PARAMETERS!$C$15/PARAMETERS!$C$17,16,20)))) | L32: =IF(K32="""","""",IF(K32=6,"PN - 6",IF(K32=10,"PN - 10",IF(K32=16,"PN - 16","PN - 20")))) | M32: =IF(OR(J32="""",J32="SIZE N/A",NOT(ISNUMBER(J32))),"""",IFERROR(SUMPRODUCT((PIPE_DB!$B$4:$B$77=J32)*(PIPE_DB!$D$4:$D$77=K32)*PIPE_DB!$E$4:$E$77),0)) | N32: =IF(OR(G32<=0,M32="""",NOT(ISNUMBER(M32))),"""",IFERROR(4*(G32/1000)/(PI()*(M32/1000)^2),0)) | O32: =IF(OR(G32<=0,M32="""",NOT(ISNUMBER(M32))),"""",IFERROR(10.67*C32*(G32/1000)^1.852/(PARAMETERS!$C$5^1.852*(M32/1000)^4.87),0)) | P32: =IF(O32="""","""",IFERROR(PARAMETERS!$C$10*O32,0)) | Q32: =IF(O32="""","""",IFERROR(O32+P32,0)) | R32: =IF(OR(D32="",E32=""),"",IFERROR($E$12-MIN(D32,E32),0)) | S32: =IF(J32="""","""",IF(J32="SIZE N/A","⚠ SIZE N/A",IF(N32="""","""",IF(AND(N32>=PARAMETERS!$C$6,N32<=PARAMETERS!$C$7,IFERROR($E$12-E32,0)>=PARAMETERS!$C$21),"✓ OK",IF(N32<PARAMETERS!$C$6,"⚠ LOW VELOCITY",IF(N32>PARAMETERS!$C$7,"⚠ HIGH VELOCITY","⚠ LOW PRESSURE"))))))
A33: 11 | F33: =IF(OR(D33="",E33=""),"",E33-D33) | G33: $E$9 | H33: =PARAMETERS!$C$22 | I33: =IF(G33<=0,"""",IFERROR(MAX(1000*((10.67*(G33/1000)^1.852)/(PARAMETERS!$C$5^1.852*(H33/1000)))^(1/4.87),1000*SQRT(4*(G33/1000)/(PI()*PARAMETERS!$C$7))),0)) | J33: =IF(OR(G33<=0,I33=""""),"""",IFERROR(AGGREGATE(15,6,PIPE_DB!$B$4:$B$77/((PIPE_DB!$E$4:$E$77>=I33)*(PIPE_DB!$D$4:$D$77=K33)),1),"SIZE N/A")) | K33: =IF(R33="""","""",IF(R33<=PARAMETERS!$C$13/PARAMETERS!$C$17,6,IF(R33<=PARAMETERS!$C$14/PARAMETERS!$C$17,10,IF(R33<=PARAMETERS!$C$15/PARAMETERS!$C$17,16,20)))) | L33: =IF(K33="""","""",IF(K33=6,"PN - 6",IF(K33=10,"PN - 10",IF(K33=16,"PN - 16","PN - 20")))) | M33: =IF(OR(J33="""",J33="SIZE N/A",NOT(ISNUMBER(J33))),"""",IFERROR(SUMPRODUCT((PIPE_DB!$B$4:$B$77=J33)*(PIPE_DB!$D$4:$D$77=K33)*PIPE_DB!$E$4:$E$77),0)) | N33: =IF(OR(G33<=0,M33="""",NOT(ISNUMBER(M33))),"""",IFERROR(4*(G33/1000)/(PI()*(M33/1000)^2),0)) | O33: =IF(OR(G33<=0,M33="""",NOT(ISNUMBER(M33))),"""",IFERROR(10.67*C33*(G33/1000)^1.852/(PARAMETERS!$C$5^1.852*(M33/1000)^4.87),0)) | P33: =IF(O33="""","""",IFERROR(PARAMETERS!$C$10*O33,0)) | Q33: =IF(O33="""","""",IFERROR(O33+P33,0)) | R33: =IF(OR(D33="",E33=""),"",IFERROR($E$12-MIN(D33,E33),0)) | S33: =IF(J33="""","""",IF(J33="SIZE N/A","⚠ SIZE N/A",IF(N33="""","""",IF(AND(N33>=PARAMETERS!$C$6,N33<=PARAMETERS!$C$7,IFERROR($E$12-E33,0)>=PARAMETERS!$C$21),"✓ OK",IF(N33<PARAMETERS!$C$6,"⚠ LOW VELOCITY",IF(N33>PARAMETERS!$C$7,"⚠ HIGH VELOCITY","⚠ LOW PRESSURE"))))))
A34: 12 | F34: =IF(OR(D34="",E34=""),"",E34-D34) | G34: $E$9 | H34: =PARAMETERS!$C$22 | I34: =IF(G34<=0,"""",IFERROR(MAX(1000*((10.67*(G34/1000)^1.852)/(PARAMETERS!$C$5^1.852*(H34/1000)))^(1/4.87),1000*SQRT(4*(G34/1000)/(PI()*PARAMETERS!$C$7))),0)) | J34: =IF(OR(G34<=0,I34=""""),"""",IFERROR(AGGREGATE(15,6,PIPE_DB!$B$4:$B$77/((PIPE_DB!$E$4:$E$77>=I34)*(PIPE_DB!$D$4:$D$77=K34)),1),"SIZE N/A")) | K34: =IF(R34="""","""",IF(R34<=PARAMETERS!$C$13/PARAMETERS!$C$17,6,IF(R34<=PARAMETERS!$C$14/PARAMETERS!$C$17,10,IF(R34<=PARAMETERS!$C$15/PARAMETERS!$C$17,16,20)))) | L34: =IF(K34="""","""",IF(K34=6,"PN - 6",IF(K34=10,"PN - 10",IF(K34=16,"PN - 16","PN - 20")))) | M34: =IF(OR(J34="""",J34="SIZE N/A",NOT(ISNUMBER(J34))),"""",IFERROR(SUMPRODUCT((PIPE_DB!$B$4:$B$77=J34)*(PIPE_DB!$D$4:$D$77=K34)*PIPE_DB!$E$4:$E$77),0)) | N34: =IF(OR(G34<=0,M34="""",NOT(ISNUMBER(M34))),"""",IFERROR(4*(G34/1000)/(PI()*(M34/1000)^2),0)) | O34: =IF(OR(G34<=0,M34="""",NOT(ISNUMBER(M34))),"""",IFERROR(10.67*C34*(G34/1000)^1.852/(PARAMETERS!$C$5^1.852*(M34/1000)^4.87),0)) | P34: =IF(O34="""","""",IFERROR(PARAMETERS!$C$10*O34,0)) | Q34: =IF(O34="""","""",IFERROR(O34+P34,0)) | R34: =IF(OR(D34="",E34=""),"",IFERROR($E$12-MIN(D34,E34),0)) | S34: =IF(J34="""","""",IF(J34="SIZE N/A","⚠ SIZE N/A",IF(N34="""","""",IF(AND(N34>=PARAMETERS!$C$6,N34<=PARAMETERS!$C$7,IFERROR($E$12-E34,0)>=PARAMETERS!$C$21),"✓ OK",IF(N34<PARAMETERS!$C$6,"⚠ LOW VELOCITY",IF(N34>PARAMETERS!$C$7,"⚠ HIGH VELOCITY","⚠ LOW PRESSURE"))))))
A35: TOTALS | C35: =IFERROR(SUM(C23:C34),0) | O35: =IFERROR(SUM(O23:O34),0) | P35: =IFERROR(SUM(P23:P34),0) | Q35: =IFERROR(SUM(Q23:Q34),0)
A37: SECTION 4 — TOTAL DYNAMIC HEAD SUMMARY
A38: 1. Static Head (Reservoir HWL – Pumping WL Elevation) | E38: =IFERROR(E12-(E5-E7),0) | F38: m
A39: 2. Total Pipeline Friction Losses | E39: =IFERROR(SUM(O23:O34),0) | F39: m
A40: 3. Total Minor Losses (fittings, bends, valves, entrance & exit) | E40: =IFERROR(SUM(P23:P34),0) | F40: m
A41: 4. Velocity Head at Discharge (V²/2g, last active segment) | E41: =IFERROR(LOOKUP(2,1/(G23:G34>0),N23:N34)^2/(2*9.81),0) | F41: m
A43: TOTAL DYNAMIC HEAD (TDH) | E43: =IFERROR(E38+E39+E40+E41,0) | F43: m
A45: SECTION 5 — PUMP REQUIREMENTS
A46: Design Flow Rate | E46: =E9 | F46: L/s
...

Sheet TRANSMISSION
A1: TRANSMISSION MAIN PIPE SIZING — Hazen-Williams Method
A2: HDPE PE100 | Auto Pipe OD & Pressure Rating (PN) Selection | Uganda WSS DM 2nd Ed.
A4: DESIGN BASIS
A5: Source Description (e.g. Borehole BH-1 / Production Well)
A6: Destination Description (e.g. Service Reservoir SR-1)
A7: Total Design Flow Q | F7: L/s | G7: Pump design capacity
A8: HGL at Supply Point | F8: m ASL | G8: Pumped: enter pump TDH + dynamic WL elevation (from TDH_CALC). Gravity: enter reservoir HWL.
A9: Allowable Head Loss Gradient | E9: =PARAMETERS!$C$22 | F9: m/km | G9: From PARAMETERS — override if needed
A10: Min. Residual Head at Destination | E10: =PARAMETERS!$C$21 | F10: m | G10: From PARAMETERS — override if needed
A12: ℹ HOW TO USE: (1) Enter segment data below — From/To Node names, Length, Elevations, and Flow Q. (2) OD and PN Rating auto-selected via AGGREGATE formula from PIPE_DB — no manual lookup needed. (3) HGL chains automatically: Segment 1 start = Supply HGL above; each subsequent start = previous end (col T). (4) BRANCHES: override HGL Start (col I) by typing =T{upstream_row} to link to the branch junction. (5) Adjust Flow Q where flow changes (e.g. at a distribution offtake). (6) Resize pipe by changing the Allowable S in the Design Basis above.
A14: STATUS KEY: | E14: ✓ OK | F14: ⚠ LOW VELOCITY | G14: ⚠ HIGH VELOCITY | H14: ⚠ LOW PRESSURE | I14: ⚠ SIZE N/A
A15: # | B15: From Node | C15: To Node | D15: Length (m) | E15: From Elev (m ASL) | F15: To Elev (m ASL) | G15: ΔElev (m) | H15: Flow Q (L/s) | I15: HGL Start (m ASL) | J15: Max Working Pressure (m) | K15: Auto PN Num | L15: Auto PN Rating | M15: Min D_req (mm) | N15: Auto OD (mm) | O15: Actual ID (mm) | P15: Velocity (m/s) | Q15: Friction hf (m) | R15: Minor Loss (m) | S15: Total Loss (m) | T15: HGL End (m ASL) | U15: Pressure at End (m) | V15: Status
A16: 1 | G16: =IF(OR(E16="",F16=""),"",F16-E16) | H16: $E$7 | I16: =$E$8 | J16: =IF(OR(E16="",I16=""),"",IFERROR(I16-MIN(E16,F16),0)) | K16: =IF(J16="""","""",IF(J16<=PARAMETERS!$C$13/PARAMETERS!$C$17,6,IF(J16<=PARAMETERS!$C$14/PARAMETERS!$C$17,10,IF(J16<=PARAMETERS!$C$15/PARAMETERS!$C$17,16,20)))) | L16: =IF(K16="""","""",IF(K16=6,"PN - 6",IF(K16=10,"PN - 10",IF(K16=16,"PN - 16","PN - 20")))) | M16: =IF(H16<=0,"""",IFERROR(MAX(1000*((10.67*(H16/1000)^1.852)/(PARAMETERS!$C$5^1.852*($E$9/1000)))^(1/4.87),1000*SQRT(4*(H16/1000)/(PI()*PARAMETERS!$C$7))),0)) | N16: =IF(OR(H16<=0,M16=""""),"""",IFERROR(AGGREGATE(15,6,PIPE_DB!$B$4:$B$77/((PIPE_DB!$E$4:$E$77>=M16)*(PIPE_DB!$D$4:$D$77=K16)),1),"SIZE N/A")) | O16: =IF(OR(N16="""",N16="SIZE N/A",NOT(ISNUMBER(N16))),"""",IFERROR(SUMPRODUCT((PIPE_DB!$B$4:$B$77=N16)*(PIPE_DB!$D$4:$D$77=K16)*PIPE_DB!$E$4:$E$77),0)) | P16: =IF(OR(H16<=0,O16="""",NOT(ISNUMBER(O16))),"""",IFERROR(4*(H16/1000)/(PI()*(O16/1000)^2),0)) | Q16: =IF(OR(H16<=0,O16="""",NOT(ISNUMBER(O16))),"""",IFERROR(10.67*D16*(H16/1000)^1.852/(PARAMETERS!$C$5^1.852*(O16/1000)^4.87),0)) | R16: =IF(Q16="""","""",IFERROR(PARAMETERS!$C$10*Q16,0)) | S16: =IF(Q16="""","""",IFERROR(Q16+R16,0)) | T16: =IF(OR(I16="""",S16=""""),"""",IFERROR(I16-S16,0)) | U16: =IF(T16="""","""",IFERROR(T16-F16,0)) | V16: =IF(N16="""","""",IF(N16="SIZE N/A","⚠ SIZE N/A",IF(P16="""","""",IF(AND(P16>=PARAMETERS!$C$6,P16<=PARAMETERS!$C$7,U16>=PARAMETERS!$C$21),"✓ OK",IF(P16<PARAMETERS!$C$6,"⚠ LOW VELOCITY",IF(P16>PARAMETERS!$C$7,"⚠ HIGH VELOCITY","⚠ LOW PRESSURE"))))))
A17: 2 | G17: =IF(OR(E17="",F17=""),"",F17-E17) | I17: =IFERROR(T16,"") | J17: =IF(OR(E17="",I17=""),"",IFERROR(I17-MIN(E17,F17),0)) | K17: =IF(J17="""","""",IF(J17<=PARAMETERS!$C$13/PARAMETERS!$C$17,6,IF(J17<=PARAMETERS!$C$14/PARAMETERS!$C$17,10,IF(J17<=PARAMETERS!$C$15/PARAMETERS!$C$17,16,20)))) | L17: =IF(K17="""","""",IF(K17=6,"PN - 6",IF(K17=10,"PN - 10",IF(K17=16,"PN - 16","PN - 20")))) | M17: =IF(H17<=0,"""",IFERROR(MAX(1000*((10.67*(H17/1000)^1.852)/(PARAMETERS!$C$5^1.852*($E$9/1000)))^(1/4.87),1000*SQRT(4*(H17/1000)/(PI()*PARAMETERS!$C$7))),0)) | N17: =IF(OR(H17<=0,M17=""""),"""",IFERROR(AGGREGATE(15,6,PIPE_DB!$B$4:$B$77/((PIPE_DB!$E$4:$E$77>=M17)*(PIPE_DB!$D$4:$D$77=K17)),1),"SIZE N/A")) | O17: =IF(OR(N17="""",N17="SIZE N/A",NOT(ISNUMBER(N17))),"""",IFERROR(SUMPRODUCT((PIPE_DB!$B$4:$B$77=N17)*(PIPE_DB!$D$4:$D$77=K17)*PIPE_DB!$E$4:$E$77),0)) | P17: =IF(OR(H17<=0,O17="""",NOT(ISNUMBER(O17))),"""",IFERROR(4*(H17/1000)/(PI()*(O17/1000)^2),0)) | Q17: =IF(OR(H17<=0,O17="""",NOT(ISNUMBER(O17))),"""",IFERROR(10.67*D17*(H17/1000)^1.852/(PARAMETERS!$C$5^1.852*(O17/1000)^4.87),0)) | R17: =IF(Q17="""","""",IFERROR(PARAMETERS!$C$10*Q17,0)) | S17: =IF(Q17="""","""",IFERROR(Q17+R17,0)) | T17: =IF(OR(I17="""",S17=""""),"""",IFERROR(I17-S17,0)) | U17: =IF(T17="""","""",IFERROR(T17-F17,0)) | V17: =IF(N17="""","""",IF(N17="SIZE N/A","⚠ SIZE N/A",IF(P17="""","""",IF(AND(P17>=PARAMETERS!$C$6,P17<=PARAMETERS!$C$7,U17>=PARAMETERS!$C$21),"✓ OK",IF(P17<PARAMETERS!$C$6,"⚠ LOW VELOCITY",IF(P17>PARAMETERS!$C$7,"⚠ HIGH VELOCITY","⚠ LOW PRESSURE"))))))
A18: 3 | G18: =IF(OR(E18="",F18=""),"",F18-E18) | I18: =IFERROR(T17,"") | J18: =IF(OR(E18="",I18=""),"",IFERROR(I18-MIN(E18,F18),0)) | K18: =IF(J18="""","""",IF(J18<=PARAMETERS!$C$13/PARAMETERS!$C$17,6,IF(J18<=PARAMETERS!$C$14/PARAMETERS!$C$17,10,IF(J18<=PARAMETERS!$C$15/PARAMETERS!$C$17,16,20)))) | L18: =IF(K18="""","""",IF(K18=6,"PN - 6",IF(K18=10,"PN - 10",IF(K18=16,"PN - 16","PN - 20")))) | M18: =IF(H18<=0,"""",IFERROR(MAX(1000*((10.67*(H18/1000)^1.852)/(PARAMETERS!$C$5^1.852*($E$9/1000)))^(1/4.87),1000*SQRT(4*(H18/1000)/(PI()*PARAMETERS!$C$7))),0)) | N18: =IF(OR(H18<=0,M18=""""),"""",IFERROR(AGGREGATE(15,6,PIPE_DB!$B$4:$B$77/((PIPE_DB!$E$4:$E$77>=M18)*(PIPE_DB!$D$4:$D$77=K18)),1),"SIZE N/A")) | O18: =IF(OR(N18="""",N18="SIZE N/A",NOT(ISNUMBER(N18))),"""",IFERROR(SUMPRODUCT((PIPE_DB!$B$4:$B$77=N18)*(PIPE_DB!$D$4:$D$77=K18)*PIPE_DB!$E$4:$E$77),0)) | P18: =IF(OR(H18<=0,O18="""",NOT(ISNUMBER(O18))),"""",IFERROR(4*(H18/1000)/(PI()*(O18/1000)^2),0)) | Q18: =IF(OR(H18<=0,O18="""",NOT(ISNUMBER(O18))),"""",IFERROR(10.67*D18*(H18/1000)^1.852/(PARAMETERS!$C$5^1.852*(O18/1000)^4.87),0)) | R18: =IF(Q18="""","""",IFERROR(PARAMETERS!$C$10*Q18,0)) | S18: =IF(Q18="""","""",IFERROR(Q18+R18,0)) | T18: =IF(OR(I18="""",S18=""""),"""",IFERROR(I18-S18,0)) | U18: =IF(T18="""","""",IFERROR(T18-F18,0)) | V18: =IF(N18="""","""",IF(N18="SIZE N/A","⚠ SIZE N/A",IF(P18="""","""",IF(AND(P18>=PARAMETERS!$C$6,P18<=PARAMETERS!$C$7,U18>=PARAMETERS!$C$21),"✓ OK",IF(P18<PARAMETERS!$C$6,"⚠ LOW VELOCITY",IF(P18>PARAMETERS!$C$7,"⚠ HIGH VELOCITY","⚠ LOW PRESSURE"))))))
A19: 4 | G19: =IF(OR(E19="",F19=""),"",F19-E19) | I19: =IFERROR(T18,"") | J19: =IF(OR(E19="",I19=""),"",IFERROR(I19-MIN(E19,F19),0)) | K19: =IF(J19="""","""",IF(J19<=PARAMETERS!$C$13/PARAMETERS!$C$17,6,IF(J19<=PARAMETERS!$C$14/PARAMETERS!$C$17,10,IF(J19<=PARAMETERS!$C$15/PARAMETERS!$C$17,16,20)))) | L19: =IF(K19="""","""",IF(K19=6,"PN - 6",IF(K19=10,"PN - 10",IF(K19=16,"PN - 16","PN - 20")))) | M19: =IF(H19<=0,"""",IFERROR(MAX(1000*((10.67*(H19/1000)^1.852)/(PARAMETERS!$C$5^1.852*($E$9/1000)))^(1/4.87),1000*SQRT(4*(H19/1000)/(PI()*PARAMETERS!$C$7))),0)) | N19: =IF(OR(H19<=0,M19=""""),"""",IFERROR(AGGREGATE(15,6,PIPE_DB!$B$4:$B$77/((PIPE_DB!$E$4:$E$77>=M19)*(PIPE_DB!$D$4:$D$77=K19)),1),"SIZE N/A")) | O19: =IF(OR(N19="""",N19="SIZE N/A",NOT(ISNUMBER(N19))),"""",IFERROR(SUMPRODUCT((PIPE_DB!$B$4:$B$77=N19)*(PIPE_DB!$D$4:$D$77=K19)*PIPE_DB!$E$4:$E$77),0)) | P19: =IF(OR(H19<=0,O19="""",NOT(ISNUMBER(O19))),"""",IFERROR(4*(H19/1000)/(PI()*(O19/1000)^2),0)) | Q19: =IF(OR(H19<=0,O19="""",NOT(ISNUMBER(O19))),"""",IFERROR(10.67*D19*(H19/1000)^1.852/(PARAMETERS!$C$5^1.852*(O19/1000)^4.87),0)) | R19: =IF(Q19="""","""",IFERROR(PARAMETERS!$C$10*Q19,0)) | S19: =IF(Q19="""","""",IFERROR(Q19+R19,0)) | T19: =IF(OR(I19="""",S19=""""),"""",IFERROR(I19-S19,0)) | U19: =IF(T19="""","""",IFERROR(T19-F19,0)) | V19: =IF(N19="""","""",IF(N19="SIZE N/A","⚠ SIZE N/A",IF(P19="""","""",IF(AND(P19>=PARAMETERS!$C$6,P19<=PARAMETERS!$C$7,U19>=PARAMETERS!$C$21),"✓ OK",IF(P19<PARAMETERS!$C$6,"⚠ LOW VELOCITY",IF(P19>PARAMETERS!$C$7,"⚠ HIGH VELOCITY","⚠ LOW PRESSURE"))))))
A20: 5 | G20: =IF(OR(E20="",F20=""),"",F20-E20) | I20: =IFERROR(T19,"") | J20: =IF(OR(E20="",I20=""),"",IFERROR(I20-MIN(E20,F20),0)) | K20: =IF(J20="""","""",IF(J20<=PARAMETERS!$C$13/PARAMETERS!$C$17,6,IF(J20<=PARAMETERS!$C$14/PARAMETERS!$C$17,10,IF(J20<=PARAMETERS!$C$15/PARAMETERS!$C$17,16,20)))) | L20: =IF(K20="""","""",IF(K20=6,"PN - 6",IF(K20=10,"PN - 10",IF(K20=16,"PN - 16","PN - 20")))) | M20: =IF(H20<=0,"""",IFERROR(MAX(1000*((10.67*(H20/1000)^1.852)/(PARAMETERS!$C$5^1.852*($E$9/1000)))^(1/4.87),1000*SQRT(4*(H20/1000)/(PI()*PARAMETERS!$C$7))),0)) | N20: =IF(OR(H20<=0,M20=""""),"""",IFERROR(AGGREGATE(15,6,PIPE_DB!$B$4:$B$77/((PIPE_DB!$E$4:$E$77>=M20)*(PIPE_DB!$D$4:$D$77=K20)),1),"SIZE N/A")) | O20: =IF(OR(N20="""",N20="SIZE N/A",NOT(ISNUMBER(N20))),"""",IFERROR(SUMPRODUCT((PIPE_DB!$B$4:$B$77=N20)*(PIPE_DB!$D$4:$D$77=K20)*PIPE_DB!$E$4:$E$77),0)) | P20: =IF(OR(H20<=0,O20="""",NOT(ISNUMBER(O20))),"""",IFERROR(4*(H20/1000)/(PI()*(O20/1000)^2),0)) | Q20: =IF(OR(H20<=0,O20="""",NOT(ISNUMBER(O20))),"""",IFERROR(10.67*D20*(H20/1000)^1.852/(PARAMETERS!$C$5^1.852*(O20/1000)^4.87),0)) | R20: =IF(Q20="""","""",IFERROR(PARAMETERS!$C$10*Q20,0)) | S20: =IF(Q20="""","""",IFERROR(Q20+R20,0)) | T20: =IF(OR(I20="""",S20=""""),"""",IFERROR(I20-S20,0)) | U20: =IF(T20="""","""",IFERROR(T20-F20,0)) | V20: =IF(N20="""","""",IF(N20="SIZE N/A","⚠ SIZE N/A",IF(P20="""","""",IF(AND(P20>=PARAMETERS!$C$6,P20<=PARAMETERS!$C$7,U20>=PARAMETERS!$C$21),"✓ OK",IF(P20<PARAMETERS!$C$6,"⚠ LOW VELOCITY",IF(P20>PARAMETERS!$C$7,"⚠ HIGH VELOCITY","⚠ LOW PRESSURE"))))))
A21: 6 | G21: =IF(OR(E21="",F21=""),"",F21-E21) | I21: =IFERROR(T20,"") | J21: =IF(OR(E21="",I21=""),"",IFERROR(I21-MIN(E21,F21),0)) | K21: =IF(J21="""","""",IF(J21<=PARAMETERS!$C$13/PARAMETERS!$C$17,6,IF(J21<=PARAMETERS!$C$14/PARAMETERS!$C$17,10,IF(J21<=PARAMETERS!$C$15/PARAMETERS!$C$17,16,20)))) | L21: =IF(K21="""","""",IF(K21=6,"PN - 6",IF(K21=10,"PN - 10",IF(K21=16,"PN - 16","PN - 20")))) | M21: =IF(H21<=0,"""",IFERROR(MAX(1000*((10.67*(H21/1000)^1.852)/(PARAMETERS!$C$5^1.852*($E$9/1000)))^(1/4.87),1000*SQRT(4*(H21/1000)/(PI()*PARAMETERS!$C$7))),0)) | N21: =IF(OR(H21<=0,M21=""""),"""",IFERROR(AGGREGATE(15,6,PIPE_DB!$B$4:$B$77/((PIPE_DB!$E$4:$E$77>=M21)*(PIPE_DB!$D$4:$D$77=K21)),1),"SIZE N/A")) | O21: =IF(OR(N21="""",N21="SIZE N/A",NOT(ISNUMBER(N21))),"""",IFERROR(SUMPRODUCT((PIPE_DB!$B$4:$B$77=N21)*(PIPE_DB!$D$4:$D$77=K21)*PIPE_DB!$E$4:$E$77),0)) | P21: =IF(OR(H21<=0,O21="""",NOT(ISNUMBER(O21))),"""",IFERROR(4*(H21/1000)/(PI()*(O21/1000)^2),0)) | Q21: =IF(OR(H21<=0,O21="""",NOT(ISNUMBER(O21))),"""",IFERROR(10.67*D21*(H21/1000)^1.852/(PARAMETERS!$C$5^1.852*(O21/1000)^4.87),0)) | R21: =IF(Q21="""","""",IFERROR(PARAMETERS!$C$10*Q21,0)) | S21: =IF(Q21="""","""",IFERROR(Q21+R21,0)) | T21: =IF(OR(I21="""",S21=""""),"""",IFERROR(I21-S21,0)) | U21: =IF(T21="""","""",IFERROR(T21-F21,0)) | V21: =IF(N21="""","""",IF(N21="SIZE N/A","⚠ SIZE N/A",IF(P21="""","""",IF(AND(P21>=PARAMETERS!$C$6,P21<=PARAMETERS!$C$7,U21>=PARAMETERS!$C$21),"✓ OK",IF(P21<PARAMETERS!$C$6,"⚠ LOW VELOCITY",IF(P21>PARAMETERS!$C$7,"⚠ HIGH VELOCITY","⚠ LOW PRESSURE"))))))
A22: 7 | G22: =IF(OR(E22="",F22=""),"",F22-E22) | I22: =IFERROR(T21,"") | J22: =IF(OR(E22="",I22=""),"",IFERROR(I22-MIN(E22,F22),0)) | K22: =IF(J22="""","""",IF(J22<=PARAMETERS!$C$13/PARAMETERS!$C$17,6,IF(J22<=PARAMETERS!$C$14/PARAMETERS!$C$17,10,IF(J22<=PARAMETERS!$C$15/PARAMETERS!$C$17,16,20)))) | L22: =IF(K22="""","""",IF(K22=6,"PN - 6",IF(K22=10,"PN - 10",IF(K22=16,"PN - 16","PN - 20")))) | M22: =IF(H22<=0,"""",IFERROR(MAX(1000*((10.67*(H22/1000)^1.852)/(PARAMETERS!$C$5^1.852*($E$9/1000)))^(1/4.87),1000*SQRT(4*(H22/1000)/(PI()*PARAMETERS!$C$7))),0)) | N22: =IF(OR(H22<=0,M22=""""),"""",IFERROR(AGGREGATE(15,6,PIPE_DB!$B$4:$B$77/((PIPE_DB!$E$4:$E$77>=M22)*(PIPE_DB!$D$4:$D$77=K22)),1),"SIZE N/A")) | O22: =IF(OR(N22="""",N22="SIZE N/A",NOT(ISNUMBER(N22))),"""",IFERROR(SUMPRODUCT((PIPE_DB!$B$4:$B$77=N22)*(PIPE_DB!$D$4:$D$77=K22)*PIPE_DB!$E$4:$E$77),0)) | P22: =IF(OR(H22<=0,O22="""",NOT(ISNUMBER(O22))),"""",IFERROR(4*(H22/1000)/(PI()*(O22/1000)^2),0)) | Q22: =IF(OR(H22<=0,O22="""",NOT(ISNUMBER(O22))),"""",IFERROR(10.67*D22*(H22/1000)^1.852/(PARAMETERS!$C$5^1.852*(O22/1000)^4.87),0)) | R22: =IF(Q22="""","""",IFERROR(PARAMETERS!$C$10*Q22,0)) | S22: =IF(Q22="""","""",IFERROR(Q22+R22,0)) | T22: =IF(OR(I22="""",S22=""""),"""",IFERROR(I22-S22,0)) | U22: =IF(T22="""","""",IFERROR(T22-F22,0)) | V22: =IF(N22="""","""",IF(N22="SIZE N/A","⚠ SIZE N/A",IF(P22="""","""",IF(AND(P22>=PARAMETERS!$C$6,P22<=PARAMETERS!$C$7,U22>=PARAMETERS!$C$21),"✓ OK",IF(P22<PARAMETERS!$C$6,"⚠ LOW VELOCITY",IF(P22>PARAMETERS!$C$7,"⚠ HIGH VELOCITY","⚠ LOW PRESSURE"))))))
A23: 8 | G23: =IF(OR(E23="",F23=""),"",F23-E23) | I23: =IFERROR(T22,"") | J23: =IF(OR(E23="",I23=""),"",IFERROR(I23-MIN(E23,F23),0)) | K23: =IF(J23="""","""",IF(J23<=PARAMETERS!$C$13/PARAMETERS!$C$17,6,IF(J23<=PARAMETERS!$C$14/PARAMETERS!$C$17,10,IF(J23<=PARAMETERS!$C$15/PARAMETERS!$C$17,16,20)))) | L23: =IF(K23="""","""",IF(K23=6,"PN - 6",IF(K23=10,"PN - 10",IF(K23=16,"PN - 16","PN - 20")))) | M23: =IF(H23<=0,"""",IFERROR(MAX(1000*((10.67*(H23/1000)^1.852)/(PARAMETERS!$C$5^1.852*($E$9/1000)))^(1/4.87),1000*SQRT(4*(H23/1000)/(PI()*PARAMETERS!$C$7))),0)) | N23: =IF(OR(H23<=0,M23=""""),"""",IFERROR(AGGREGATE(15,6,PIPE_DB!$B$4:$B$77/((PIPE_DB!$E$4:$E$77>=M23)*(PIPE_DB!$D$4:$D$77=K23)),1),"SIZE N/A")) | O23: =IF(OR(N23="""",N23="SIZE N/A",NOT(ISNUMBER(N23))),"""",IFERROR(SUMPRODUCT((PIPE_DB!$B$4:$B$77=N23)*(PIPE_DB!$D$4:$D$77=K23)*PIPE_DB!$E$4:$E$77),0)) | P23: =IF(OR(H23<=0,O23="""",NOT(ISNUMBER(O23))),"""",IFERROR(4*(H23/1000)/(PI()*(O23/1000)^2),0)) | Q23: =IF(OR(H23<=0,O23="""",NOT(ISNUMBER(O23))),"""",IFERROR(10.67*D23*(H23/1000)^1.852/(PARAMETERS!$C$5^1.852*(O23/1000)^4.87),0)) | R23: =IF(Q23="""","""",IFERROR(PARAMETERS!$C$10*Q23,0)) | S23: =IF(Q23="""","""",IFERROR(Q23+R23,0)) | T23: =IF(OR(I23="""",S23=""""),"""",IFERROR(I23-S23,0)) | U23: =IF(T23="""","""",IFERROR(T23-F23,0)) | V23: =IF(N23="""","""",IF(N23="SIZE N/A","⚠ SIZE N/A",IF(P23="""","""",IF(AND(P23>=PARAMETERS!$C$6,P23<=PARAMETERS!$C$7,U23>=PARAMETERS!$C$21),"✓ OK",IF(P23<PARAMETERS!$C$6,"⚠ LOW VELOCITY",IF(P23>PARAMETERS!$C$7,"⚠ HIGH VELOCITY","⚠ LOW PRESSURE"))))))
A24: 9 | G24: =IF(OR(E24="",F24=""),"",F24-E24) | I24: =IFERROR(T23,"") | J24: =IF(OR(E24="",I24=""),"",IFERROR(I24-MIN(E24,F24),0)) | K24: =IF(J24="""","""",IF(J24<=PARAMETERS!$C$13/PARAMETERS!$C$17,6,IF(J24<=PARAMETERS!$C$14/PARAMETERS!$C$17,10,IF(J24<=PARAMETERS!$C$15/PARAMETERS!$C$17,16,20)))) | L24: =IF(K24="""","""",IF(K24=6,"PN - 6",IF(K24=10,"PN - 10",IF(K24=16,"PN - 16","PN - 20")))) | M24: =IF(H24<=0,"""",IFERROR(MAX(1000*((10.67*(H24/1000)^1.852)/(PARAMETERS!$C$5^1.852*($E$9/1000)))^(1/4.87),1000*SQRT(4*(H24/1000)/(PI()*PARAMETERS!$C$7))),0)) | N24: =IF(OR(H24<=0,M24=""""),"""",IFERROR(AGGREGATE(15,6,PIPE_DB!$B$4:$B$77/((PIPE_DB!$E$4:$E$77>=M24)*(PIPE_DB!$D$4:$D$77=K24)),1),"SIZE N/A")) | O24: =IF(OR(N24="""",N24="SIZE N/A",NOT(ISNUMBER(N24))),"""",IFERROR(SUMPRODUCT((PIPE_DB!$B$4:$B$77=N24)*(PIPE_DB!$D$4:$D$77=K24)*PIPE_DB!$E$4:$E$77),0)) | P24: =IF(OR(H24<=0,O24="""",NOT(ISNUMBER(O24))),"""",IFERROR(4*(H24/1000)/(PI()*(O24/1000)^2),0)) | Q24: =IF(OR(H24<=0,O24="""",NOT(ISNUMBER(O24))),"""",IFERROR(10.67*D24*(H24/1000)^1.852/(PARAMETERS!$C$5^1.852*(O24/1000)^4.87),0)) | R24: =IF(Q24="""","""",IFERROR(PARAMETERS!$C$10*Q24,0)) | S24: =IF(Q24="""","""",IFERROR(Q24+R24,0)) | T24: =IF(OR(I24="""",S24=""""),"""",IFERROR(I24-S24,0)) | U24: =IF(T24="""","""",IFERROR(T24-F24,0)) | V24: =IF(N24="""","""",IF(N24="SIZE N/A","⚠ SIZE N/A",IF(P24="""","""",IF(AND(P24>=PARAMETERS!$C$6,P24<=PARAMETERS!$C$7,U24>=PARAMETERS!$C$21),"✓ OK",IF(P24<PARAMETERS!$C$6,"⚠ LOW VELOCITY",IF(P24>PARAMETERS!$C$7,"⚠ HIGH VELOCITY","⚠ LOW PRESSURE"))))))
A25: 10 | G25: =IF(OR(E25="",F25=""),"",F25-E25) | I25: =IFERROR(T24,"") | J25: =IF(OR(E25="",I25=""),"",IFERROR(I25-MIN(E25,F25),0)) | K25: =IF(J25="""","""",IF(J25<=PARAMETERS!$C$13/PARAMETERS!$C$17,6,IF(J25<=PARAMETERS!$C$14/PARAMETERS!$C$17,10,IF(J25<=PARAMETERS!$C$15/PARAMETERS!$C$17,16,20)))) | L25: =IF(K25="""","""",IF(K25=6,"PN - 6",IF(K25=10,"PN - 10",IF(K25=16,"PN - 16","PN - 20")))) | M25: =IF(H25<=0,"""",IFERROR(MAX(1000*((10.67*(H25/1000)^1.852)/(PARAMETERS!$C$5^1.852*($E$9/1000)))^(1/4.87),1000*SQRT(4*(H25/1000)/(PI()*PARAMETERS!$C$7))),0)) | N25: =IF(OR(H25<=0,M25=""""),"""",IFERROR(AGGREGATE(15,6,PIPE_DB!$B$4:$B$77/((PIPE_DB!$E$4:$E$77>=M25)*(PIPE_DB!$D$4:$D$77=K25)),1),"SIZE N/A")) | O25: =IF(OR(N25="""",N25="SIZE N/A",NOT(ISNUMBER(N25))),"""",IFERROR(SUMPRODUCT((PIPE_DB!$B$4:$B$77=N25)*(PIPE_DB!$D$4:$D$77=K25)*PIPE_DB!$E$4:$E$77),0)) | P25: =IF(OR(H25<=0,O25="""",NOT(ISNUMBER(O25))),"""",IFERROR(4*(H25/1000)/(PI()*(O25/1000)^2),0)) | Q25: =IF(OR(H25<=0,O25="""",NOT(ISNUMBER(O25))),"""",IFERROR(10.67*D25*(H25/1000)^1.852/(PARAMETERS!$C$5^1.852*(O25/1000)^4.87),0)) | R25: =IF(Q25="""","""",IFERROR(PARAMETERS!$C$10*Q25,0)) | S25: =IF(Q25="""","""",IFERROR(Q25+R25,0)) | T25: =IF(OR(I25="""",S25=""""),"""",IFERROR(I25-S25,0)) | U25: =IF(T25="""","""",IFERROR(T25-F25,0)) | V25: =IF(N25="""","""",IF(N25="SIZE N/A","⚠ SIZE N/A",IF(P25="""","""",IF(AND(P25>=PARAMETERS!$C$6,P25<=PARAMETERS!$C$7,U25>=PARAMETERS!$C$21),"✓ OK",IF(P25<PARAMETERS!$C$6,"⚠ LOW VELOCITY",IF(P25>PARAMETERS!$C$7,"⚠ HIGH VELOCITY","⚠ LOW PRESSURE"))))))
A26: 11 | G26: =IF(OR(E26="",F26=""),"",F26-E26) | I26: =IFERROR(T25,"") | J26: =IF(OR(E26="",I26=""),"",IFERROR(I26-MIN(E26,F26),0)) | K26: =IF(J26="""","""",IF(J26<=PARAMETERS!$C$13/PARAMETERS!$C$17,6,IF(J26<=PARAMETERS!$C$14/PARAMETERS!$C$17,10,IF(J26<=PARAMETERS!$C$15/PARAMETERS!$C$17,16,20)))) | L26: =IF(K26="""","""",IF(K26=6,"PN - 6",IF(K26=10,"PN - 10",IF(K26=16,"PN - 16","PN - 20")))) | M26: =IF(H26<=0,"""",IFERROR(MAX(1000*((10.67*(H26/1000)^1.852)/(PARAMETERS!$C$5^1.852*($E$9/1000)))^(1/4.87),1000*SQRT(4*(H26/1000)/(PI()*PARAMETERS!$C$7))),0)) | N26: =IF(OR(H26<=0,M26=""""),"""",IFERROR(AGGREGATE(15,6,PIPE_DB!$B$4:$B$77/((PIPE_DB!$E$4:$E$77>=M26)*(PIPE_DB!$D$4:$D$77=K26)),1),"SIZE N/A")) | O26: =IF(OR(N26="""",N26="SIZE N/A",NOT(ISNUMBER(N26))),"""",IFERROR(SUMPRODUCT((PIPE_DB!$B$4:$B$77=N26)*(PIPE_DB!$D$4:$D$77=K26)*PIPE_DB!$E$4:$E$77),0)) | P26: =IF(OR(H26<=0,O26="""",NOT(ISNUMBER(O26))),"""",IFERROR(4*(H26/1000)/(PI()*(O26/1000)^2),0)) | Q26: =IF(OR(H26<=0,O26="""",NOT(ISNUMBER(O26))),"""",IFERROR(10.67*D26*(H26/1000)^1.852/(PARAMETERS!$C$5^1.852*(O26/1000)^4.87),0)) | R26: =IF(Q26="""","""",IFERROR(PARAMETERS!$C$10*Q26,0)) | S26: =IF(Q26="""","""",IFERROR(Q26+R26,0)) | T26: =IF(OR(I26="""",S26=""""),"""",IFERROR(I26-S26,0)) | U26: =IF(T26="""","""",IFERROR(T26-F26,0)) | V26: =IF(N26="""","""",IF(N26="SIZE N/A","⚠ SIZE N/A",IF(P26="""","""",IF(AND(P26>=PARAMETERS!$C$6,P26<=PARAMETERS!$C$7,U26>=PARAMETERS!$C$21),"✓ OK",IF(P26<PARAMETERS!$C$6,"⚠ LOW VELOCITY",IF(P26>PARAMETERS!$C$7,"⚠ HIGH VELOCITY","⚠ LOW PRESSURE"))))))
A27: 12 | G27: =IF(OR(E27="",F27=""),"",F27-E27) | I27: =IFERROR(T26,"") | J27: =IF(OR(E27="",I27=""),"",IFERROR(I27-MIN(E27,F27),0)) | K27: =IF(J27="""","""",IF(J27<=PARAMETERS!$C$13/PARAMETERS!$C$17,6,IF(J27<=PARAMETERS!$C$14/PARAMETERS!$C$17,10,IF(J27<=PARAMETERS!$C$15/PARAMETERS!$C$17,16,20)))) | L27: =IF(K27="""","""",IF(K27=6,"PN - 6",IF(K27=10,"PN - 10",IF(K27=16,"PN - 16","PN - 20")))) | M27: =IF(H27<=0,"""",IFERROR(MAX(1000*((10.67*(H27/1000)^1.852)/(PARAMETERS!$C$5^1.852*($E$9/1000)))^(1/4.87),1000*SQRT(4*(H27/1000)/(PI()*PARAMETERS!$C$7))),0)) | N27: =IF(OR(H27<=0,M27=""""),"""",IFERROR(AGGREGATE(15,6,PIPE_DB!$B$4:$B$77/((PIPE_DB!$E$4:$E$77>=M27)*(PIPE_DB!$D$4:$D$77=K27)),1),"SIZE N/A")) | O27: =IF(OR(N27="""",N27="SIZE N/A",NOT(ISNUMBER(N27))),"""",IFERROR(SUMPRODUCT((PIPE_DB!$B$4:$B$77=N27)*(PIPE_DB!$D$4:$D$77=K27)*PIPE_DB!$E$4:$E$77),0)) | P27: =IF(OR(H27<=0,O27="""",NOT(ISNUMBER(O27))),"""",IFERROR(4*(H27/1000)/(PI()*(O27/1000)^2),0)) | Q27: =IF(OR(H27<=0,O27="""",NOT(ISNUMBER(O27))),"""",IFERROR(10.67*D27*(H27/1000)^1.852/(PARAMETERS!$C$5^1.852*(O27/1000)^4.87),0)) | R27: =IF(Q27="""","""",IFERROR(PARAMETERS!$C$10*Q27,0)) | S27: =IF(Q27="""","""",IFERROR(Q27+R27,0)) | T27: =IF(OR(I27="""",S27=""""),"""",IFERROR(I27-S27,0)) | U27: =IF(T27="""","""",IFERROR(T27-F27,0)) | V27: =IF(N27="""","""",IF(N27="SIZE N/A","⚠ SIZE N/A",IF(P27="""","""",IF(AND(P27>=PARAMETERS!$C$6,P27<=PARAMETERS!$C$7,U27>=PARAMETERS!$C$21),"✓ OK",IF(P27<PARAMETERS!$C$6,"⚠ LOW VELOCITY",IF(P27>PARAMETERS!$C$7,"⚠ HIGH VELOCITY","⚠ LOW PRESSURE"))))))
A28: 13 | G28: =IF(OR(E28="",F28=""),"",F28-E28) | I28: =IFERROR(T27,"") | J28: =IF(OR(E28="",I28=""),"",IFERROR(I28-MIN(E28,F28),0)) | K28: =IF(J28="""","""",IF(J28<=PARAMETERS!$C$13/PARAMETERS!$C$17,6,IF(J28<=PARAMETERS!$C$14/PARAMETERS!$C$17,10,IF(J28<=PARAMETERS!$C$15/PARAMETERS!$C$17,16,20)))) | L28: =IF(K28="""","""",IF(K28=6,"PN - 6",IF(K28=10,"PN - 10",IF(K28=16,"PN - 16","PN - 20")))) | M28: =IF(H28<=0,"""",IFERROR(MAX(1000*((10.67*(H28/1000)^1.852)/(PARAMETERS!$C$5^1.852*($E$9/1000)))^(1/4.87),1000*SQRT(4*(H28/1000)/(PI()*PARAMETERS!$C$7))),0)) | N28: =IF(OR(H28<=0,M28=""""),"""",IFERROR(AGGREGATE(15,6,PIPE_DB!$B$4:$B$77/((PIPE_DB!$E$4:$E$77>=M28)*(PIPE_DB!$D$4:$D$77=K28)),1),"SIZE N/A")) | O28: =IF(OR(N28="""",N28="SIZE N/A",NOT(ISNUMBER(N28))),"""",IFERROR(SUMPRODUCT((PIPE_DB!$B$4:$B$77=N28)*(PIPE_DB!$D$4:$D$77=K28)*PIPE_DB!$E$4:$E$77),0)) | P28: =IF(OR(H28<=0,O28="""",NOT(ISNUMBER(O28))),"""",IFERROR(4*(H28/1000)/(PI()*(O28/1000)^2),0)) | Q28: =IF(OR(H28<=0,O28="""",NOT(ISNUMBER(O28))),"""",IFERROR(10.67*D28*(H28/1000)^1.852/(PARAMETERS!$C$5^1.852*(O28/1000)^4.87),0)) | R28: =IF(Q28="""","""",IFERROR(PARAMETERS!$C$10*Q28,0)) | S28: =IF(Q28="""","""",IFERROR(Q28+R28,0)) | T28: =IF(OR(I28="""",S28=""""),"""",IFERROR(I28-S28,0)) | U28: =IF(T28="""","""",IFERROR(T28-F28,0)) | V28: =IF(N28="""","""",IF(N28="SIZE N/A","⚠ SIZE N/A",IF(P28="""","""",IF(AND(P28>=PARAMETERS!$C$6,P28<=PARAMETERS!$C$7,U28>=PARAMETERS!$C$21),"✓ OK",IF(P28<PARAMETERS!$C$6,"⚠ LOW VELOCITY",IF(P28>PARAMETERS!$C$7,"⚠ HIGH VELOCITY","⚠ LOW PRESSURE"))))))
... A30: 15 | G30: =IF(OR(E30="",F30=""),"",F30-E30) | I30: =IFERROR(T29,"") | J30: =IF(OR(E30="",I30=""),"",IFERROR(I30-MIN(E30,F30),0)) | K30: =IF(J30="""","""",IF(J30<=PARAMETERS!$C$13/PARAMETERS!$C$17,6,IF(J30<=PARAMETERS!$C$14/PARAMETERS!$C$17,10,IF(J30<=PARAMETERS!$C$15/PARAMETERS!$C$17,16,20)))) | L30: =IF(K30="""","""",IF(K30=6,"PN - 6",IF(K30=10,"PN - 10",IF(K30=16,"PN - 16","PN - 20")))) | M30: =IF(H30<=0,"""",IFERROR(MAX(1000*((10.67*(H30/1000)^1.852)/(PARAMETERS!$C$5^1.852*($E$9/1000)))^(1/4.87),1000*SQRT(4*(H30/1000)/(PI()*PARAMETERS!$C$7))),0)) | N30: =IF(OR(H30<=0,M30=""""),"""",IFERROR(AGGREGATE(15,6,PIPE_DB!$B$4:$B$77/((PIPE_DB!$E$4:$E$77>=M30)*(PIPE_DB!$D$4:$D$77=K30)),1),"SIZE N/A")) | O30: =IF(OR(N30="""",N30="SIZE N/A",NOT(ISNUMBER(N30))),"""",IFERROR(SUMPRODUCT((PIPE_DB!$B$4:$B$77=N30)*(PIPE_DB!$D$4:$D$77=K30)*PIPE_DB!$E$4:$E$77),0)) | P30: =IF(OR(H30<=0,O30="""",NOT(ISNUMBER(O30))),"""",IFERROR(4*(H30/1000)/(PI()*(O30/1000)^2),0)) | Q30: =IF(OR(H30<=0,O30="""",NOT(ISNUMBER(O30))),"""",IFERROR(10.67*D30*(H30/1000)^1.852/(PARAMETERS!$C$5^1.852*(O30/1000)^4.87),0)) | R30: =IF(Q30="""","""",IFERROR(PARAMETERS!$C$10*Q30,0)) | S30: =IF(Q30="""","""",IFERROR(Q30+R30,0)) | T30: =IF(OR(I30="""",S30=""""),"""",IFERROR(I30-S30,0)) | U30: =IF(T30="""","""",IFERROR(T30-F30,0)) | V30: =IF(N30="""","""",IF(N30="SIZE N/A","⚠ SIZE N/A",IF(P30="""","""",IF(AND(P30>=PARAMETERS!$C$6,P30<=PARAMETERS!$C$7,U30>=PARAMETERS!$C$21),"✓ OK",IF(P30<PARAMETERS!$C$6,"⚠ LOW VELOCITY",IF(P30>PARAMETERS!$C$7,"⚠ HIGH VELOCITY","⚠ LOW PRESSURE"))))))
A31: TOTALS | D31: =IFERROR(SUM(D16:D30),0) | Q31: =IFERROR(SUM(Q16:Q30),0) | R31: =IFERROR(SUM(R16:R30),0) | S31: =IFERROR(SUM(S16:S30),0)
A33: HYDRAULIC SUMMARY
A34: Total Pipeline Length | E34: =IFERROR(SUM(D16:D30),0) | F34: m
A35: Total Friction Head Loss | E35: =IFERROR(SUM(Q16:Q30),0) | F35: m
A36: Total Minor Head Loss | E36: =IFERROR(SUM(R16:R30),0) | F36: m
A37: Total Head Loss (friction+minor) | E37: =IFERROR(SUM(S16:S30),0) | F37: m
A38: HGL at Supply Point | E38: =$E$8 | F38: m ASL
A39: HGL at Destination | E39: =IFERROR(T30,"-") | F39: m ASL
A40: Residual Head at Destination | E40: =IFERROR(U30,"-") | F40: m
A41: Required Minimum Residual Head | E41: =$E$10 | F41: m
A42: Design Check | E42: =IF(ISNUMBER(U30),IF(U30>=$E$10,"✓ SUFFICIENT HEAD","⚠ INSUFFICIENT HEAD — REVISE DESIGN"),"-")

Sheet DISTRIBUTION
A1: DISTRIBUTION NETWORK PIPE SIZING — Hazen-Williams Method
A2: HDPE PE100 | Auto Pipe OD & Pressure Rating (PN) Selection | Uganda WSS DM 2nd Ed.
A4: SECTION 1 — DEMAND CALCULATION
A5: Parameter | B5: Value | C5: Unit | D5: Notes / Formula
A6: Present Population | C6: persons | D6: Current census / community count
A7: Design Population (auto-calculated) | B7: =IFERROR(B6*(1+PARAMETERS!$C$31)^PARAMETERS!$C$32,"") | C7: persons | D7: Present pop × (1 + growth rate)^design period
A8: Per Capita Demand | B8: =PARAMETERS!$C$27 | C8: L/cap/day | D8: From PARAMETERS — adjust to local survey data
A9: NRW / Loss Factor | B9: =PARAMETERS!$C$30 | C9: - | D9: From PARAMETERS
A10: Peak Hour Factor (PHF) | B10: =PARAMETERS!$C$28 | C10: - | D10: From PARAMETERS
A11: Gross Average Daily Demand | B11: =IFERROR(B7*B8*B9/1000,"") | C11: m³/day | D11: Design pop × per_capita × NRW ÷ 1000
A12: Average Daily Flow | B12: =IFERROR(B11*1000/(24*3600),"") | C12: L/s | D12: Gross ADD × 1000 ÷ 86400
A13: DESIGN FLOW — Peak Hour (use per branch below) | B13: =IFERROR(B12*B10,"") | C13: L/s | D13: Average daily flow × PHF
A14: HGL at Supply Point (Reservoir HWL) | C14: m ASL | D14: Enter reservoir high water level from TDH_CALC or survey
A15: Min. Residual Pressure at Consumer | B15: =PARAMETERS!$C$20 | C15: m | D15: From PARAMETERS — Uganda WSS DM rural standard
A16: Allowable Head Loss Gradient | B16: =PARAMETERS!$C$23 | C16: m/km | D16: From PARAMETERS — override if needed
A18: ℹ BRANCHING GUIDANCE: Enter each pipe branch as one row. Set 'HGL Start' (col H) manually: • First pipe from reservoir: type =B14 (reservoir HWL). • Continuation (series): type =S{previous_row} to link to the preceding pipe's HGL End. • Branch from junction: type =S{junction_row} to link to the junction node's HGL End. Flow Q = flow carried by THAT branch only (not cumulative upstream flow). Colour coding shows hydraulic status instantly.
A19: STATUS KEY: | E19: ✓ OK | F19: ⚠ LOW VELOCITY | G19: ⚠ HIGH VELOCITY | H19: ⚠ LOW PRESSURE | I19: ⚠ SIZE N/A
A21: # | B21: From Node | C21: To Node | D21: Length (m) | E21: From Elev (m ASL) | F21: To Elev (m ASL) | G21: Flow Q (L/s) | H21: HGL Start (m ASL) [INPUT] | I21: Max Working Pressure (m) | J21: Auto PN Num | K21: Auto PN Rating | L21: Min D_req (mm) | M21: Auto OD (mm) | N21: Actual ID (mm) | O21: Velocity (m/s) | P21: Friction hf (m) | Q21: Minor Loss (m) | R21: Total Loss (m) | S21: HGL End (m ASL) | T21: Pressure at End (m) | U21: Status
A22: 1 | H22: =$B$14 | I22: =IF(OR(E22="",H22=""),"",IFERROR(H22-MIN(E22,F22),0)) | J22: =IF(I22="""","""",IF(I22<=PARAMETERS!$C$13/PARAMETERS!$C$17,6,IF(I22<=PARAMETERS!$C$14/PARAMETERS!$C$17,10,IF(I22<=PARAMETERS!$C$15/PARAMETERS!$C$17,16,20)))) | K22: =IF(J22="""","""",IF(J22=6,"PN - 6",IF(J22=10,"PN - 10",IF(J22=16,"PN - 16","PN - 20")))) | L22: =IF(G22<=0,"""",IFERROR(MAX(1000*((10.67*(G22/1000)^1.852)/(PARAMETERS!$C$5^1.852*($B$16/1000)))^(1/4.87),1000*SQRT(4*(G22/1000)/(PI()*PARAMETERS!$C$9))),0)) | M22: =IF(OR(G22<=0,L22=""""),"""",IFERROR(AGGREGATE(15,6,PIPE_DB!$B$4:$B$77/((PIPE_DB!$E$4:$E$77>=L22)*(PIPE_DB!$D$4:$D$77=J22)),1),"SIZE N/A")) | N22: =IF(OR(M22="""",M22="SIZE N/A",NOT(ISNUMBER(M22))),"""",IFERROR(SUMPRODUCT((PIPE_DB!$B$4:$B$77=M22)*(PIPE_DB!$D$4:$D$77=J22)*PIPE_DB!$E$4:$E$77),0)) | O22: =IF(OR(G22<=0,N22="""",NOT(ISNUMBER(N22))),"""",IFERROR(4*(G22/1000)/(PI()*(N22/1000)^2),0)) | P22: =IF(OR(G22<=0,N22="""",NOT(ISNUMBER(N22))),"""",IFERROR(10.67*D22*(G22/1000)^1.852/(PARAMETERS!$C$5^1.852*(N22/1000)^4.87),0)) | Q22: =IF(P22="""","""",IFERROR(PARAMETERS!$C$10*P22,0)) | R22: =IF(P22="""","""",IFERROR(P22+Q22,0)) | S22: =IF(OR(H22="""",R22=""""),"""",IFERROR(H22-R22,0)) | T22: =IF(S22="""","""",IFERROR(S22-F22,0)) | U22: =IF(M22="""","""",IF(M22="SIZE N/A","⚠ SIZE N/A",IF(O22="""","""",IF(AND(O22>=PARAMETERS!$C$8,O22<=PARAMETERS!$C$9,T22>=PARAMETERS!$C$20),"✓ OK",IF(O22<PARAMETERS!$C$8,"⚠ LOW VELOCITY",IF(O22>PARAMETERS!$C$9,"⚠ HIGH VELOCITY","⚠ LOW PRESSURE"))))))
A23: 2 | I23: =IF(OR(E23="",H23=""),"",IFERROR(H23-MIN(E23,F23),0)) | J23: =IF(I23="""","""",IF(I23<=PARAMETERS!$C$13/PARAMETERS!$C$17,6,IF(I23<=PARAMETERS!$C$14/PARAMETERS!$C$17,10,IF(I23<=PARAMETERS!$C$15/PARAMETERS!$C$17,16,20)))) | K23: =IF(J23="""","""",IF(J23=6,"PN - 6",IF(J23=10,"PN - 10",IF(J23=16,"PN - 16","PN - 20")))) | L23: =IF(G23<=0,"""",IFERROR(MAX(1000*((10.67*(G23/1000)^1.852)/(PARAMETERS!$C$5^1.852*($B$16/1000)))^(1/4.87),1000*SQRT(4*(G23/1000)/(PI()*PARAMETERS!$C$9))),0)) | M23: =IF(OR(G23<=0,L23=""""),"""",IFERROR(AGGREGATE(15,6,PIPE_DB!$B$4:$B$77/((PIPE_DB!$E$4:$E$77>=L23)*(PIPE_DB!$D$4:$D$77=J23)),1),"SIZE N/A")) | N23: =IF(OR(M23="""",M23="SIZE N/A",NOT(ISNUMBER(M23))),"""",IFERROR(SUMPRODUCT((PIPE_DB!$B$4:$B$77=M23)*(PIPE_DB!$D$4:$D$77=J23)*PIPE_DB!$E$4:$E$77),0)) | O23: =IF(OR(G23<=0,N23="""",NOT(ISNUMBER(N23))),"""",IFERROR(4*(G23/1000)/(PI()*(N23/1000)^2),0)) | P23: =IF(OR(G23<=0,N23="""",NOT(ISNUMBER(N23))),"""",IFERROR(10.67*D23*(G23/1000)^1.852/(PARAMETERS!$C$5^1.852*(N23/1000)^4.87),0)) | Q23: =IF(P23="""","""",IFERROR(PARAMETERS!$C$10*P23,0)) | R23: =IF(P23="""","""",IFERROR(P23+Q23,0)) | S23: =IF(OR(H23="""",R23=""""),"""",IFERROR(H23-R23,0)) | T23: =IF(S23="""","""",IFERROR(S23-F23,0)) | U23: =IF(M23="""","""",IF(M23="SIZE N/A","⚠ SIZE N/A",IF(O23="""","""",IF(AND(O23>=PARAMETERS!$C$8,O23<=PARAMETERS!$C$9,T23>=PARAMETERS!$C$20),"✓ OK",IF(O23<PARAMETERS!$C$8,"⚠ LOW VELOCITY",IF(O23>PARAMETERS!$C$9,"⚠ HIGH VELOCITY","⚠ LOW PRESSURE"))))))
